## ✅ 전체 코드 핵심 요약

```java
try {
    func(); // 예외 발생
} catch (NullPointerException e) {
    sum += 1;
} catch (Exception e) {
    sum += 10;
} finally {
    sum += 100;
}
```

---

## 🔎 `func()`에서 발생하는 예외는?

```java
static void func() throws Exception {
    throw new NullPointerException();
}
```

* `NullPointerException` 예외를 강제로 발생시킴

> ※ 참고: `NullPointerException`은 `RuntimeException` → `Exception`의 자식 클래스

---

## 🔁 예외 흐름 분석

### 1. `func();` 실행

* `throw new NullPointerException();` 실행되면서 → 예외 발생

### 2. catch 블록 탐색

* 첫 번째 catch:

  ```java
  catch (NullPointerException e) → ✅ 이곳에서 잡힘!
  ```

  → `sum = sum + 1;` 실행 → `sum == 1`

* 두 번째 catch는 실행되지 않음 (이미 예외 처리됐기 때문)

### 3. finally 블록

* 무조건 실행되는 블록

  ```java
  finally {
      sum = sum + 100;  // ✅ 실행됨
  }
  ```

  → `sum == 1 + 100 = 101`

---

## 🧾 최종 출력 결과

```java
System.out.print(sum); → 출력값: 101
```

---

## ✅ 정답: `101`

---

## 💡 예외 처리 흐름 요약

| 구간                            | 실행 여부 | sum 변화  |
| ----------------------------- | ----- | ------- |
| `func()`                      | 예외 발생 | -       |
| `catch(NullPointerException)` | 실행    | `+1`    |
| `catch(Exception)`            | 건너뜀   | -       |
| `finally`                     | 항상 실행 | `+100`  |
| **합계**                        |       | **101** |

---

궁금한 점:

* `throws Exception`이 왜 붙었는지
* `catch`의 순서가 왜 중요한지
* `finally`가 언제 실행되는지

이런 부분들도 더 알고 싶으면 언제든지 물어보세요! 😊
